Workbook
Name actionlist: #REF!
Name actionlist: #REF!
Name Adopted_Value: [4]DCF_Approach!$F$9
Name Adopted_Value: #REF!
Name Block.5Yr: '[5]sino-p35'!$J$36:$O$41
Name Block.5Yr: #REF!
Name block.Assumptions.blue: #REF!
Name block.Assumptions.blue: #REF!
Name block.Author.blue: #REF!
Name block.Author.blue: #REF!
Name Block.BalSheet: '[5]sino-p35'!$B$27:$G$58
Name Block.BalSheet: #REF!
Name Block.Cashflow: '[5]sino-p35'!$J$7:$O$25
Name Block.Cashflow: #REF!
Name Block.CorpStruct: '[5]sino-p35'!$J$60:$O$67
Name Block.CorpStruct: #REF!
Name block.Expansion.blue: #REF!
Name block.Expansion.blue: #REF!
Name block.Forecasts.blue: #REF!
Name block.Forecasts.blue: #REF!
Name Block.Free: '[5]sino-p35'!$J$26:$O$41
Name Block.Free: #REF!
Name block.IncomeStatement.blue: #REF!
Name block.IncomeStatement.blue: #REF!
Name block.KeyData.blue: #REF!
Name block.KeyData.blue: #REF!
Name block.Miscellaneous.blue: #REF!
Name block.Miscellaneous.blue: #REF!
Name block.Miscellaneous.none: #REF!
Name block.Miscellaneous.none: #REF!
Name Block.Profit: '[5]sino-p35'!$B$7:$G$22
Name Block.Profit: #REF!
Name Block.Ratios: '[5]sino-p35'!$J$27:$O$32
Name Block.Ratios: #REF!
Name block.SalesBreakdown.blue: #REF!
Name block.SalesBreakdown.blue: #REF!
Name block.Subsidiaries.blue: #REF!
Name block.Subsidiaries.blue: #REF!
Name Bot_Tenant: '[7]Tenancy Analysis'!$B$475
Name Bot_Tenant: #REF!
Name Building_Description: [4]Model!$F$17
Name Building_Description: #REF!
Name CC: [8]Summaries!$A$2:$B$181
Name CC: #REF!
Name churn1: #REF!
Name churn1: [9]!churn1
Name churn1: #REF!
Name churn1: #REF!
Name churn1: #REF!
Name churn1: #REF!
Name churn1: #REF!
Name churn1: #REF!
Name churn1: #REF!
Name churn1: #REF!
Name churn1: #REF!
Name Co_Name: '[10]Key data'!$A$1
Name Co_Name: #REF!
Name Core_Cap: [4]Model!$F$41
Name Core_Cap: #REF!
Name COSCO_Capacity_Growth: #REF!

Sheet Title
A1: Mapletree Quarterly Market Research Study
A6: Seoul Office
A9: Prepared by: Colliers
D11: [INSERT PICTURE OF THE MARKET]

Sheet Map
A1: Seoul Map of Grade A Office Building Submarkets

Sheet Map_II
A1: Seoul Map of Grade A Office Building Submarkets_II

Sheet Macro Econ>>

Sheet Macro
A1: Supporting Docs 2a: Key Macroeconomic Highlights - For Each Market | N1: Note from Colliers: Section will be further updated with release of 2Q 2025 data.
A3: As requested, please find the latest economic highlights for the various markets.
A5: Singapore Retail
A7: 1. GDP Forecast
A8: - Based on advance estimates, Singapore’s GDP grew by 4.1% in 3Q 2024, extending the 2.9% growth in 2Q 2024.
A9: - For whole of 2023, GDP grew by 1.1%. Singapore's economy is forecasted to grow by 2% to 3% in 2024.
A10: 2. Retail Sales
A11: - Retail sales (excluding motor vehicles) in August 2024 declined 1.5% yoy, overall retail sales in 2Q 2024 down 2.7% yoy.
A12: - 2023 vs 2022 an increase of 1.7%.
A13: 3. Recent notable events
A14: - From Jan. 1, 2024, GST rate has increased from 8% to 9%.
A15: - Tourist arrivals recorded 12.5 million in 9M 2024, about 87.8% of the same period in 2019 before COVID. The return of mainland visitors in 9M 2024 is about 87.1% of the same period in 2019 before COVID.
A16: - STB forecasts overall international visitor arrivals in 2024 to reach around 15 to 16 million.
... A81: - Grade A prime office buildings in the core area of Teheran-ro within the GBD continues to remain popular among end-users and financial investors.

Sheet Headlines
A1: Headlines
B2: Table: Real GDP Growth Rate, Unemployment Rate, Inflation Rate and their Forecast
B3: Indicator | C3: 2017 | D3: 2018 | E3: 2019 | F3: 2020 | G3: 2021 | H3: 2022 | I3: 2023 | J3: 2024 | K3: 1Q 2025 | L3: 2Q 2025 | M3: 3Q 2025 | N3: 4Q 2025 | O3: 2025 (F) | P3: 2026 (F)
B4: Real GDP Growth Rate | C4: 0.032 | D4: 0.029 | E4: 0.022 | F4: -0.007 | G4: 0.041 | H4: 0.026 | I4: 0.014 | J4: 0.02 | K4: -0.001 | L4: 0.003 | M4: 0.013 | N4: 0.015 | O4: 0.009 | P4: 0.018
B5: YoY/QoQ | D5: =D4-C4 -> -0.003 | E5: =E4-D4 -> -0.007 | F5: =F4-E4 -> -0.029 | G5: =G4-F4 -> 0.048 | H5: =H4-G4 -> -0.015 | I5: =I4-H4 -> -0.012 | J5: =J4-I4 -> 0.006 | L5: =L4-K4 -> 0.004 | M5: =M4-L4 -> 0.01 | N5: =N4-M4 -> 0.002 | O5: =O4-J4 -> -0.011 | P5: =P4-O4 -> 0.009
B6: Inflation Rate | C6: 0.0194 | D6: 0.0148 | E6: 0.0038 | F6: 0.0054 | G6: 0.025 | H6: 0.051 | I6: 0.036 | J6: 0.023 | K6: 0.021 | L6: 0.02 | M6: 0.019 | N6: 0.021 | O6: 0.021 | P6: 0.02
B7: YoY/QoQ | D7: =D6-C6 -> -0.0046 | E7: =E6-D6 -> -0.011 | F7: =F6-E6 -> 0.0016 | G7: =G6-F6 -> 0.0196 | H7: =H6-G6 -> 0.026 | I7: =I6-H6 -> -0.015 | J7: =J6-I6 -> -0.013 | L7: =L6-K6 -> -0.001 | M7: =M6-L6 -> -0.001 | N7: =N6-M6 -> 0.002 | O7: =O6-J6 -> -0.002 | P7: =P6-O6 -> -0.001
B8: Unemployment Rate | C8: 0.037 | D8: 0.039 | E8: 0.038 | F8: 0.04 | G8: 0.037 | H8: 0.029 | I8: 0.027 | J8: 0.028 | K8: 0.034 | L8: 0.033 | M8: 0.025 | N8: 0.025 | O8: 0.028 | P8: 0.028
B9: YoY/QoQ | D9: =D8-C8 -> 0.002 | E9: =E8-D8 -> -0.001 | F9: =F8-E8 -> 0.002 | G9: =G8-F8 -> -0.003 | H9: =H8-G8 -> -0.008 | I9: =I8-H8 -> -0.002 | J9: =J8-I8 -> 0.001 | L9: =L8-K8 -> -0.001 | M9: =M8-L8 -> -0.008 | N9: =N8-M8 -> 0 | O9: =O8-J8 -> 0 | P9: =P8-O8 -> 0
B10: Source(s): KOSIS, Bank Of Korea, National Assembly, KDI | E10: =E9-D9 -> -0.003 | F10: =F9-E9 -> 0.003 | G10: =G9-F9 -> -0.005 | H10: =H9-G9 -> -0.005 | I10: =I9-H9 -> 0.006 | J10: =J9-I9 -> 0.003 | L10: =L9-K9 -> -0.001 | M10: =M9-L9 -> -0.007 | N10: =N9-M9 -> 0.008
B13: Recently, the Korean economy has continued to experience weakness in the construction sector; however, a gradual economic recovery led by consumption has been maintained. GDP increased by 0.2pp quarter-on-quarter, supported by improvements in consumption and exports, and recorded a higher year-on-year growth rate compared to the previous quarter. While domestic demand remains constrained by weak construction investment, the downturn has been partially offset by improving consumption. Facility investment continues to underperform outside the semiconductor sector, and despite an increase in construction orders, construction investment has continued to decline as orders have not translated smoothly into actual development activity. In contrast, private consumption has expanded, supported by declining market interest rates and government support measures, while government consumption has also recorded strong growth, contributing to the overall economic recovery. Employment has shown a moderate increase, mainly in the service sector, which is significantly influenced by government job programs. In 2026, Korea’s economy is expected to grow by approximately 1.8%, as domestic demand recovers despite a moderation in exports. Consumer prices are projected to rise by around 2.0%, broadly in line with this year’s 2.1%, as recovering domestic demand is offset by declining international oil prices. Employment conditions are expected to improve gradually in line with the domestic recovery; however, due to demographic structural changes, the total number of employed persons is projected to decline compared to this year.

Sheet Visitor Arrivals
A1: Seoul Tourist Arrivals
A3: Table: Number of Tourist Arrivals ('000) (Yearly)
B4: Tourist Arrivals
A5: Year | B5: Total visitor | C5: YoY Change in All Visitors
A7: 2009 | B7: 7817.533 | C7: -
A8: 2010 | B8: 8797.658 | C8: =B8/B7-1 -> 0.12537523 | E8: =B8/B7-1 -> 0.12537523
A9: 2011 | B9: 9794.796 | C9: =B9/B8-1 -> 0.1133413 | E9: =B9/B8-1 -> 0.1133413
A10: 2012 | B10: 11140.028 | C10: =B10/B9-1 -> 0.1373415 | E10: =B10/B9-1 -> 0.1373415
A11: 2013 | B11: 12175.55 | C11: =B11/B10-1 -> 0.092955063 | E11: =B11/B10-1 -> 0.092955063
A12: 2014 | B12: 14201.516 | C12: =B12/B11-1 -> 0.16639626 | E12: =B12/B11-1 -> 0.16639626
A13: 2015 | B13: 13231.651 | C13: =B13/B12-1 -> -0.068293061 | E13: =B13/B12-1 -> -0.068293061
A14: 2016 | B14: 17241.823 | C14: =B14/B13-1 -> 0.3030742 | E14: =B14/B13-1 -> 0.3030742
A15: 2017 | B15: 13335.758 | C15: =B15/B14-1 -> -0.22654594 | E15: =B15/B14-1 -> -0.22654594
A16: 2018 | B16: 15346.879 | C16: =B16/B15-1 -> 0.15080665 | E16: =B16/B15-1 -> 0.15080665
A17: 2019 | B17: 17502.756 | C17: =B17/B16-1 -> 0.14047658 | E17: =B17/B16-1 -> 0.14047658
A18: 2020 | B18: 2519.118 | C18: =B18/B17-1 -> -0.85607307 | E18: =B18/B17-1 -> -0.85607307
A19: 2021 | B19: 967.003 | C19: =B19/B18-1 -> -0.6161343 | E19: =B19/B18-1 -> -0.6161343
A20: 2022 | B20: =C177/1000 -> 3198.017 | C20: =B20/B19-1 -> 2.3071428 | E20: =B20/B19-1 -> 2.3071428
A21: 2023 | B21: =(J138/1000) -> 11031.665 | C21: =B21/B20-1 -> 2.4495329
A22: 2024 | B22: =SUM(J139:J150)/1000 -> 16369.609 | C22: =B22/B21-1 -> 0.48387474
A23: 2025 (Oct) | B23: =(SUM(J152:J163)/1000) -> 15821.331 | C23: =B23/B22-1 -> -0.033493653
A24: Source: VisitKorea Data Lab
A26: In 2025, South Korea’s inbound tourism continued its recovery trajectory, supported by the normalization of international travel, expanded flight capacity, and the gradual return of key source markets. While Chinese visitor volumes recovered at a slower pace compared to pre-pandemic levels, growth was led by travelers from Japan, Southeast Asia, and North America, driven by favorable exchange rates, improved air connectivity, and sustained interest in Korean culture and entertainment. The rebound in inbound tourism supported improvements in hotel occupancy and RevPAR, particularly in Seoul and major metropolitan areas, with demand concentrated in leisure-oriented districts and well-connected urban locations. Looking ahead, inbound tourism is expected to remain on a gradual growth path, underpinned by visa facilitation measures, major international events, and continued expansion of low-cost and full-service airline routes.
A42: Table: Number of Tourist Arrivals (Monthly)
C43: Tourist Arrivals | J43: Tourist Arrivals
A44: Year | B44: Month | C44: Total visitor | D44: YoY Change in All Visitors | H44: Year | I44: Month | J44: Total visitor | K44: YoY Change in All Visitors
A46: 2009 | B46: 1 | C46: 607659 | H46: 2015 | I46: 1 | J46: 917054
B47: 2 | C47: 666928 | I47: 2 | J47: 1050706
B48: 3 | C48: 724117 | I48: 3 | J48: 1238144
B49: 4 | C49: 688586 | I49: 4 | J49: 1384567
B50: 5 | C50: 574559 | I50: 5 | J50: 1334212
B51: 6 | C51: 530506 | I51: 6 | J51: 750925
B52: 7 | C52: 609258 | I52: 7 | J52: 629737
B53: 8 | C53: 695880 | I53: 8 | J53: 1069314
B54: 9 | C54: 678691 | I54: 9 | J54: 1206764
B55: 10 | C55: 737373 | I55: 10 | J55: 1383704
B56: 11 | C56: 642672 | I56: 11 | J56: 1150074
B57: 12 | C57: 661304 | I57: 12 | J57: 1116450
B58: Total | C58: 7817533 | D58: - | I58: Total | J58: 13231651 | K58: =(J58-C123)/C123 -> -0.068293061
A59: 2010 | B59: 1 | C59: 569453 | H59: 2016 | I59: 1 | J59: 1077431
...

Sheet Retail Sales Trend
A1: Seoul Retail Sales Trend
A3: Table: Retail Sales & Proportion of Online Sales
B4: FOREX: respective KRW/USD by month used for caluation
A5: Month-Year | B5: Monthly Total Retail Sales ($ Billion) | C5: Monthly Online Sales ($ Billion) | D5: Monthly Physical Sales ($ Billion) | E5: Proportion of Online Retail Sales | G5: MoM | H5: YoY
B6: Retail Total | C6: Online Retail Sales | D6: Physical Retail Sales | E6: % of Online Retail Sales
A7: 43739 | B7: 30.392561 | C7: 8.9772974 | D7: =B7-C7 -> 21.415264 | E7: =C7/B7 -> 0.29537811
A8: 43770 | B8: 31.360099 | C8: 9.7126234 | D8: =B8-C8 -> 21.647475 | E8: =C8/B8 -> 0.30971278 | G8: =C8/C7-1 -> 0.081909502
A9: 43800 | B9: 31.80501 | C9: 9.6020858 | D9: =B9-C9 -> 22.202925 | E9: =C9/B9 -> 0.30190482 | G9: =C9/C8-1 -> -0.011380811
A10: 43831 | B10: 29.555722 | C10: 9.0506355 | D10: =B10-C10 -> 20.505087 | E10: =C10/B10 -> 0.30622278 | G10: =C10/C9-1 -> -0.057430268
A11: 43862 | B11: 25.859803 | C11: 8.8117285 | D11: =B11-C11 -> 17.048074 | E11: =C11/B11 -> 0.34075003 | G11: =C11/C10-1 -> -0.02639671
A12: 43891 | B12: 28.009406 | C12: 9.2667516 | D12: =B12-C12 -> 18.742655 | E12: =C12/B12 -> 0.33084427 | G12: =C12/C11-1 -> 0.051638356
A13: 43922 | B13: 28.203891 | C13: 8.8703686 | D13: =B13-C13 -> 19.333523 | E13: =C13/B13 -> 0.31450868 | G13: =C13/C12-1 -> -0.04277476
A14: 43952 | B14: 30.618291 | C14: 9.3542158 | D14: =B14-C14 -> 21.264075 | E14: =C14/B14 -> 0.30551071 | G14: =C14/C13-1 -> 0.054546458
A15: 43983 | B15: 30.322935 | C15: 9.2877826 | D15: =B15-C15 -> 21.035153 | E15: =C15/B15 -> 0.30629563 | G15: =C15/C14-1 -> -0.0071019491
A16: 44013 | B16: 28.978743 | C16: 9.5440573 | D16: =B16-C16 -> 19.434685 | E16: =C16/B16 -> 0.32934684 | G16: =C16/C15-1 -> 0.027592665
A17: 44044 | B17: 29.342496 | C17: 9.9497989 | D17: =B17-C17 -> 19.392697 | E17: =C17/B17 -> 0.33909177 | G17: =C17/C16-1 -> 0.042512489
A18: 44075 | B18: 31.413343 | C18: 10.237086 | D18: =B18-C18 -> 21.176257 | E18: =C18/B18 -> 0.32588336 | G18: =C18/C17-1 -> 0.028873642
A19: 44105 | B19: 30.548737 | C19: 10.275361 | D19: =B19-C19 -> 20.273375 | E19: =C19/B19 -> 0.33635961 | G19: =C19/C18-1 -> 0.0037388833
A20: 44136 | B20: 31.100866 | C20: 11.125837 | D20: =B20-C20 -> 19.975028 | E20: =C20/B20 -> 0.35773401 | G20: =C20/C19-1 -> 0.0827685 | H20: =C20/C7-1 -> 0.23933037
A21: 44166 | B21: 31.329763 | C21: 11.839817 | D21: =B21-C21 -> 19.489946 | E21: =C21/B21 -> 0.37790956 | G21: =C21/C20-1 -> 0.064173104 | H21: =C21/C8-1 -> 0.21901328
A22: 44197 | B22: 29.797374 | C22: 11.092331 | D22: =B22-C22 -> 18.705043 | E22: =C22/B22 -> 0.37225867 | G22: =C22/C21-1 -> -0.063133223 | H22: =C22/C9-1 -> 0.15520016
A23: 44228 | B23: 28.435613 | C23: 10.15084 | D23: =B23-C23 -> 18.284773 | E23: =C23/B23 -> 0.35697629 | G23: =C23/C22-1 -> -0.084877694 | H23: =C23/C10-1 -> 0.12156098
A24: 44256 | B24: 31.951087 | C24: 11.597094 | D24: =B24-C24 -> 20.353993 | E24: =C24/B24 -> 0.36296399 | G24: =C24/C23-1 -> 0.14247634 | H24: =C24/C11-1 -> 0.31609753
A25: 44287 | B25: 31.848787 | C25: 10.990535 | D25: =B25-C25 -> 20.858252 | E25: =C25/B25 -> 0.34508489 | G25: =C25/C24-1 -> -0.052302651 | H25: =C25/C12-1 -> 0.18601811
A26: 44317 | B26: 32.890612 | C26: 11.697276 | D26: =B26-C26 -> 21.193336 | E26: =C26/B26 -> 0.35564178 | G26: =C26/C25-1 -> 0.064304459 | H26: =C26/C13-1 -> 0.31869106
A27: 44348 | B27: 31.944905 | C27: 11.36299 | D27: =B27-C27 -> 20.581915 | E27: =C27/B27 -> 0.35570585 | G27: =C27/C26-1 -> -0.02857811 | H27: =C27/C14-1 -> 0.21474531
A28: 44378 | B28: 32.332824 | C28: 11.699274 | D28: =B28-C28 -> 20.63355 | E28: =C28/B28 -> 0.36183891 | G28: =C28/C27-1 -> 0.02959471 | H28: =C28/C15-1 -> 0.25964125
A29: 44409 | B29: 31.585139 | C29: 11.420135 | D29: =B29-C29 -> 20.165004 | E29: =C29/B29 -> 0.3615667 | G29: =C29/C28-1 -> -0.023859558 | H29: =C29/C16-1 -> 0.19657021
A30: 44440 | B30: 33.526114 | C30: 11.671983 | D30: =B30-C30 -> 21.854131 | E30: =C30/B30 -> 0.34814603 | G30: =C30/C29-1 -> 0.022053053 | H30: =C30/C17-1 -> 0.17308737
A31: 44470 | B31: 34.093825 | C31: 12.23674 | D31: =B31-C31 -> 21.857085 | E31: =C31/B31 -> 0.35891367 | G31: =C31/C30-1 -> 0.048385631 | H31: =C31/C18-1 -> 0.19533429
... A41: 44774 | B41: 34.629107 | C41: 13.246175 | D41: =B41-C41 -> 21.382932 | E41: =C41/B41 -> 0.38251564 | G41: =C41/C40-1 -> 0.040329273 | H41: =C41/C28-1 -> 0.13222198
A42: 44805 | B42: 34.473464 | C42: 12.732676 | D42: =B42-C42 -> 21.740788 | E42: =C42/B42 -> 0.36934715 | G42: =C42/C41-1 -> -0.038765873 | H42: =C42/C29-1 -> 0.11493219 | J42: In October 2025, South Korea’s online retail sales totaled USD 15.96 billion, accounting for 40.8% of total retail sales (USD 39.10 billion), while physical retail sales reached USD 23.14 billion. On a month-on-month basis, online sales declined by 6.3%, while year-on-year growth remained positive at 8.7%. Overall, the data indicates that online penetration remains structurally high, despite short-term volatility in monthly sales performance. Year-on-year growth was driven by food services, automobiles and auto-related products, and food and beverages, while culture and leisure services declined. Specialized online malls outperformed general malls in annual growth, and omnichannel platforms recorded stronger year-on-year growth than online-only platforms, despite month-on-month declines across all segments.
A43: 44835 | B43: 33.715313 | C43: 12.435231 | D43: =B43-C43 -> 21.280082 | E43: =C43/B43 -> 0.36883036 | G43: =C43/C42-1 -> -0.02336071 | H43: =C43/C30-1 -> 0.065391452
A44: 44866 | B44: 35.934167 | C44: 13.739839 | D44: 22.194327 | E44: =C44/B44 -> 0.38236143 | G44: =C44/C43-1 -> 0.10491223 | H44: =C44/C31-1 -> 0.12283497
A45: 44896 | B45: 41.84276 | C45: 14.578981 | D45: 27.263779 | E45: =C45/B45 -> 0.34842303 | G45: =C45/C44-1 -> 0.061073636 | H45: =C45/C32-1 -> 0.15459856
A46: 44927 | B46: 42.608848 | C46: 14.38913 | D46: 28.219718 | E46: =C46/B46 -> 0.33770287 | G46: =C46/C45-1 -> -0.01302222 | H46: =C46/C33-1 -> 0.080654994
A47: 44958 | B47: 38.019641 | C47: 13.411078 | D47: 24.608564 | E47: =C47/B47 -> 0.35274078 | G47: =C47/C46-1 -> -0.067971633 | H47: =C47/C34-1 -> 0.088400752
A48: 44986 | B48: 41.617458 | C48: 14.289077 | D48: 27.32838 | E48: =C48/B48 -> 0.34334335 | G48: =C48/C47-1 -> 0.065468234 | H48: =C48/C35-1 -> 0.24014306
A49: 45017 | B49: 39.759989 | C49: 13.531354 | D49: 26.228635 | E49: =C49/B49 -> 0.34032591 | G49: =C49/C48-1 -> -0.053028131 | H49: =C49/C36-1 -> 0.050548364
A50: 45047 | B50: 41.189318 | C50: 14.491768 | D50: 26.69755 | E50: =C50/B50 -> 0.35183316 | G50: =C50/C49-1 -> 0.070976898 | H50: =C50/C37-1 -> 0.17730126
...

Sheet Retail Sales Index
A1: Seoul Retail Sales Index
A3: Table: Retail Sales Index
A4: Month-Year | B4: Retail Sales Index - YoY % change
A5: 44409 | B5: 0.173
A6: 44440 | B6: 0.236
A7: 44470 | B7: 0.274
A8: 44501 | B8: 0.285
A9: 44531 | B9: 0.313
A10: 44562 | B10: 0.221
A11: 44593 | B11: 0.112
A12: 44621 | B12: 0.275
A13: 44652 | B13: 0.29 | D13: Consumer spending has shown a gradual improvement, supported by accumulated policy rate cuts and government stimulus measures. Although retail sales growth moderated in October due to the delayed Chuseok holiday, average growth over September–October remained positive. Seasonally adjusted retail sales rose month-on-month, driven by consumption stimulus policies, while increased activity in accommodation, food services, and leisure sectors indicated a recovery in services consumption. With consumer sentiment remaining elevated, the improving consumption trend is expected to continue in the near term despite short-term fluctuations.
A14: 44682 | B14: 0.365
A15: 44713 | B15: 0.32
A16: 44743 | B16: 0.347
A17: 44774 | B17: 0.346
A18: 44805 | B18: 0.35
A19: 44835 | B19: 0.384
A20: 44866 | B20: 0.356
A21: 44896 | B21: 0.396
A22: 44927 | B22: 0.331
A23: 44958 | B23: 0.32555673
A24: 44986 | B24: 0.219
A25: 45017 | B25: 0.183
... A46: 45658 | B46: 0.253
A47: 45689 | B47: =B46+'[22]Macro_Key Financials'!$DU$794 -> 0.27242568
A48: 45717 | B48: =B47+'[22]Macro_Key Financials'!$DU$794 -> 0.29185135
A49: 45748 | B49: =B48+'[22]Macro_Key Financials'!$DV$794 -> 0.30225898
A50: 45778 | B50: =B49+'[22]Macro_Key Financials'!$DW$794 -> 0.30893121
A51: 45809 | B51: =B50+'[22]Macro_Key Financials'!$DX$794 -> 0.32458338
A52: 45839 | B52: =B51+'[22]Macro_Key Financials'!$DY$794 -> 0.36465307
A53: 45870 | B53: =B52+'[22]Macro_Key Financials'!$DZ$794 -> 0.37951321
A54: 45901 | B54: =B53+'[22]Macro_Key Financials'!$EA$794 -> 0.42058614
A55: 45931 | B55: =B54+'[22]Macro_Key Financials'!$EB$794 -> 0.44585994
A56: Source: KOSIS

Sheet Unemployment Rate
A1: Seoul Unemployment Rate
A3: Table: Unemployment Rate
A4: Year | B4: Unemployment Rate | C4: QoQ | E4: Employment conditions in South Korea continue to face delays in recovery due to prolonged weakness in the construction and manufacturing sectors. While overall job growth moderated in October, with the increase in employment narrowing from 312,000 to 193,000 month-on-month following a normalization of temporary daily employment, labor market conditions remain uneven. Employment in manufacturing and construction continued to decline, while growth in the services sector moderated as strong gains in health and welfare eased and employment in professional and scientific services turned negative. Nevertheless, employment trends in consumption-related sectors—including wholesale and retail, accommodation and food services, and arts and entertainment—showed signs of stabilization, reflecting a gradual improvement in consumer-driven demand. Overall employment and labor force participation rates remain below early-year levels, indicating a delayed labor market recovery. Employment rates declined among workers in their 20s and 30s, while those in their 40s and 50s continued to improve, and the unemployment rate remained broadly stable at 2.6%.
A5: 2006 | B5: 0.035
A6: 2007 | B6: 0.032 | C6: =B6-B5 -> -0.003
A7: 2008 | B7: 0.032 | C7: =B7-B6 -> 0
A8: 2009 | B8: 0.036 | C8: =B8-B7 -> 0.004
A9: 2010 | B9: 0.037 | C9: =B9-B8 -> 0.001
A10: 2011 | B10: 0.034 | C10: =B10-B9 -> -0.003
A11: 2012 | B11: 0.032 | C11: =B11-B10 -> -0.002
A12: 2013 | B12: 0.031 | C12: =B12-B11 -> -0.001
A13: 2014 | B13: 0.035 | C13: =B13-B12 -> 0.004
A14: 2015 | B14: 0.036 | C14: =B14-B13 -> 0.001
A15: 2016 | B15: 0.037 | C15: =B15-B14 -> 0.001
A16: 2017 | B16: 0.037 | C16: =B16-B15 -> 0
A17: 2018 | B17: 0.038 | C17: =B17-B16 -> 0.001
... A22: 2023 | B22: 0.027 | C22: =B22-B21 -> -0.002
A23: 1Q 2024 | B23: 0.028 | C23: =B23-B22 -> 0.001
A24: 2Q 2024 | B24: 0.028 | C24: =B24-B23 -> 0
A25: 3Q 2024 | B25: 0.025 | C25: =B25-B24 -> -0.003
A26: 4Q 2024 | B26: 0.024 | C26: =B26-B25 -> -0.001
A27: 1Q 2025 | B27: 0.037 | C27: =B27-B26 -> 0.013
A28: 2Q 2025 | B28: =Headlines!L8 -> 0.033 | C28: =B28-B27 -> -0.004
A29: 3Q 2025 | B29: =Headlines!M8 -> 0.025 | C29: =B29-B28 -> -0.008
A30: 4Q 2025 | B30: 0.026 | C30: =B30-B29 -> 0.001
A31: Source: KOSIS, National Assembly

Sheet Office Market>>

Sheet Office Outlook
A1: Seoul Office Outlook
A2: Outlook | B2: The Seoul office market remains resilient entering year-end 2025, supported by firm rental growth, low vacancy, and the absence of new supply in the second half of the year. However, the outlook is increasingly shaped by the contrast between tight near-term market conditions and a substantial supply pipeline from 2026 onward, which will be the key driver of market performance over the medium term. In 2025, new office supply was limited to approximately 28,437 pyeong, all delivered in the first half of the year. While Q4 2025 recorded negative net absorption, full-year absorption remained marginally positive, with the quarterly reversal reflecting year-end tenant consolidation rather than a structural weakening in demand. The ongoing Flight to Quality continues to support prime assets, sustaining low vacancy in the GBD and YBD, while the CBD faces relatively higher vacancy risk due to tenant relocations and future supply exposure. From 2026, the market will enter a period of elevated new supply, concentrated in the CBD and GBD and peaking in 2028–2029, which is expected to place upward pressure on vacancy rates and moderate rental growth. Despite these risks, investment demand remains solid, as evidenced by increased transaction activity in Q4 2025 and the growing use of share-deal structures, while cap rates have remained broadly stable. Overall, near-term rental conditions are expected to remain supportive, though medium-term performance will increasingly depend on the market’s ability to absorb the upcoming supply wave.
A8: Source: Colliers Database

Sheet Existing Supply
A1: Seoul Grade A Office Building Existing Stock
A3: Table: Distribution of existing Grade A Office Building stock by end of current quarter
A4: Grade A Office Building Stock | B4: Net (pyeong) | C4: Gross (x1.25) | D4: Completions (New Supply) | E4: Check
A5: Grade A Office Building Stock at 2021 Q4 (Net) | B5: 2701427.2 | C5: =Table24[[#This Row],[Net (pyeong)]]*1.25 -> 3376784
A6: Grade A Office Building Stock at 2022 Q4 (Net) | B6: 2701427.2 | C6: =Table24[[#This Row],[Net (pyeong)]]*1.25 -> 3376784 | D6: =Table24[[#This Row],[Net (pyeong)]]-B5 -> 0
A7: Grade A Office Building Stock at 2023 Q1 (Net) | B7: 2687094.7 | C7: =Table24[[#This Row],[Net (pyeong)]]*1.25 -> 3358868.3 | D7: =Table24[[#This Row],[Net (pyeong)]]-B6 -> -14332.494
A8: Grade A Office Building Stock at 2023 Q2 (Net) | B8: 2687094.7 | C8: =Table24[[#This Row],[Net (pyeong)]]*1.25 -> 3358868.3 | D8: =Table24[[#This Row],[Net (pyeong)]]-B7 -> 0
A9: Grade A Office Building Stock at 2023 Q3 (Net) | B9: 2704553.8 | C9: =Table24[[#This Row],[Net (pyeong)]]*1.25 -> 3380692.2 | D9: =Table24[[#This Row],[Net (pyeong)]]-B8 -> 17459.09
A10: Grade A Office Building Stock at 2023 Q4 (Net) | B10: =B11-'Future Supply'!H26*1000000 -> 2704553.8 | C10: =Table24[[#This Row],[Net (pyeong)]]*1.25 -> 3380692.2 | D10: =Table24[[#This Row],[Net (pyeong)]]-B9 -> 0
A11: Grade A Office Building Stock at 2024 Q1 (Net) | B11: =B12-'Future Supply'!H27*1000000 -> 2747415.3 | C11: =Table24[[#This Row],[Net (pyeong)]]*1.25 -> 3434269.1 | D11: =Table24[[#This Row],[Net (pyeong)]]-B10 -> 42861.521
A12: Grade A Office Building Stock at 2024 Q2 (Net) | B12: 2760162.2 | C12: 3450366.4 | D12: =Table24[[#This Row],[Net (pyeong)]]-B11 -> 12746.886
A13: Grade A Office Building Stock at 2024 Q3 (Net) | B13: =B14-('Future Supply'!H28*1000000) -> 2760162.2 | C13: =Table24[[#This Row],[Net (pyeong)]]*1.25 -> 3450202.7 | D13: =Table24[[#This Row],[Net (pyeong)]]-B12 -> 0
A14: Grade A Office Building Stock at 2024 Q4 (Net) | B14: 2768343.6 | C14: 3460429.5 | D14: =Table24[[#This Row],[Net (pyeong)]]-B13 -> 8181.3969
A15: Grade A Office Building Stock at 2025 Q1 (Net) | B15: 2780097.8 | C15: =Table24[[#This Row],[Net (pyeong)]]*1.25 -> 3475122.2 | D15: =Table24[[#This Row],[Net (pyeong)]]-B14 -> 11754.218
A16: Grade A Office Building Stock at 2025 Q2 (Net) | B16: 2808534.5 | C16: 3510668.1 | D16: =Table24[[#This Row],[Net (pyeong)]]-B15 -> 28436.674
A17: Grade A Office Building Stock at 2025 Q3 (Net) | B17: =E27 -> 2808534.5 | C17: =Table24[[#This Row],[Net (pyeong)]]*1.25 -> 3510668.1 | D17: =Table24[[#This Row],[Net (pyeong)]]-B16 -> 0
A18: Grade A Office Building Stock at 2025 Q4 (Net) | B18: =E27 -> 2808534.5 | C18: =Table24[[#This Row],[Net (pyeong)]]*1.25 -> 3510668.1 | D18: =Table24[[#This Row],[Net (pyeong)]]-B17 -> 0 | E18: =Table24[[#This Row],[Completions (New Supply)]]=D27 -> TRUE
A19: Source: Colliers Database
A21: Table: Distribution of Grade A Office Building existing stock by submarkets by end of current quarter
A23: Submarket | B23: Previous Quarter GFA (pyeong) | C23: Pecentage of Stock | D23: New Supply (pyeong) | E23: Current Quarter GFA (pyeong) | F23: Percentage of Stock
A24: CBD | B24: 1223518 | C24: =B24/$B$27 -> 0.43564285 | E24: =SUM(D24,B24) -> 1223518 | F24: =E24/$E$27 -> 0.43564285
A25: GBD | B25: 931242.62 | C25: =B25/$B$27 -> 0.331576 | E25: =SUM(D25,B25) -> 931242.62 | F25: =E25/$E$27 -> 0.331576
A26: YBD | B26: 653773.89 | C26: =B26/$B$27 -> 0.23278115 | E26: =SUM(D26,B26) -> 653773.89 | F26: =E26/$E$27 -> 0.23278115
A27: Total | B27: =SUM(B24:B26) -> 2808534.5 | C27: =SUM(C24:C26) -> 1 | D27: =SUM(D24:D26) -> 0 | E27: =SUM(E24:E26) -> 2808534.5 | F27: =SUM(F24:F26) -> 1 | H27: In 2025, all new office supply in Seoul was completed in the first half of the year, with no new office completions scheduled in the second half of year 2025. A total of 28,436.67 pyeong (GFA basis) of new office space was delivered during the year, comprising two projects in the CBD and one project in the GBD. | U27: =SUM('Future Supply'!H29:H31)*1000000 -> 28436.674
A28: Source: Colliers Database

Sheet Future Supply
A1: Seoul Future Supply
A3: Table: Future Supply (2024-2026) | E3: Table: Future Supply by Submarkets (2025-2032) | I3: Unit: pyeong | P3: Table: Future Supply Breakdown in next 5 years (2025-2030)
B4: GFA (Million pyeong) | C4: GFA (Million pyeong) including 2025 YTD | E4: Submarket | F4: 2025F | G4: 2026F | H4: 2027F | I4: 2028F | J4: 2029F | K4: 2030F | L4: 2031F | M4: 2032F | P4: Supply Breakdown (2025 -2030) | Q4: Area (Million pyeong) | R4: % of Total Supply
A5: =F4 -> 2025F | B5: =SUM(F5:F7)/1000000 -> 0 | C5: =B5+SUM(H26:H30) -> 0.071972731 | E5: CBD | F5: =1000000*SUMIFS($H$36:$H$70,$G$36:$G$70,$E5,$A$36:$A$70,LEFT(F$4,4)) -> 0 | G5: =1000000*SUMIFS($H$36:$H$70,$G$36:$G$70,$E5,$A$36:$A$70,LEFT(G$4,4)) -> 89805.21 | H5: =1000000*SUMIFS($H$36:$H$70,$G$36:$G$70,$E5,$A$36:$A$70,LEFT(H$4,4)) -> 86697.826 | I5: =1000000*SUMIFS($H$36:$H$70,$G$36:$G$70,$E5,$A$36:$A$70,LEFT(I$4,4)) -> 177686.55 | J5: =1000000*SUMIFS($H$36:$H$70,$G$36:$G$70,$E5,$A$36:$A$70,LEFT(J$4,4)) -> 318098.3 | K5: =1000000*SUMIFS($H$36:$H$70,$G$36:$G$70,$E5,$A$36:$A$70,LEFT(K$4,4)) -> 40528.345 | L5: =1000000*SUMIFS($H$36:$H$70,$G$36:$G$70,$E5,$A$36:$A$70,LEFT(L$4,4)) -> 66493.947 | M5: =1000000*SUMIFS($H$36:$H$70,$G$36:$G$70,$E5,$A$36:$A$70,LEFT(M$4,4)) -> 0 | P5: CBD | Q5: =(SUM(F5:K5)/1000000) -> 0.71281624 | R5: =Q5/$Q$8 -> 0.79758109
A6: =G4 -> 2026F | B6: =SUM(G5:G7)/1000000 -> 0.08980521 | C6: =C5+B6 -> 0.16177794 | E6: GBD | F6: =1000000*SUMIFS($H$36:$H$70,$G$36:$G$70,$E6,$A$36:$A$70,LEFT(F$4,4)) -> 0 | G6: =1000000*SUMIFS($H$36:$H$70,$G$36:$G$70,$E6,$A$36:$A$70,LEFT(G$4,4)) -> 0 | H6: =1000000*SUMIFS($H$36:$H$70,$G$36:$G$70,$E6,$A$36:$A$70,LEFT(H$4,4)) -> 0 | I6: =1000000*SUMIFS($H$36:$H$70,$G$36:$G$70,$E6,$A$36:$A$70,LEFT(I$4,4)) -> 115248.26 | J6: =1000000*SUMIFS($H$36:$H$70,$G$36:$G$70,$E6,$A$36:$A$70,LEFT(J$4,4)) -> 0 | K6: =1000000*SUMIFS($H$36:$H$70,$G$36:$G$70,$E6,$A$36:$A$70,LEFT(K$4,4)) -> 40282.412 | L6: =1000000*SUMIFS($H$36:$H$70,$G$36:$G$70,$E6,$A$36:$A$70,LEFT(L$4,4)) -> 280988.32 | M6: =1000000*SUMIFS($H$36:$H$70,$G$36:$G$70,$E6,$A$36:$A$70,LEFT(M$4,4)) -> 0 | P6: GBD | Q6: =(SUM(F6:K6)/1000000) -> 0.15553068 | R6: =Q6/$Q$8 -> 0.17402568
A7: =H4 -> 2027F | B7: =SUM(H5:H7)/1000000 -> 0.086697826 | C7: =C6+B7 -> 0.24847577 | E7: YBD | F7: =1000000*SUMIFS($H$36:$H$70,$G$36:$G$70,$E7,$A$36:$A$70,LEFT(F$4,4)) -> 0 | G7: =1000000*SUMIFS($H$36:$H$70,$G$36:$G$70,$E7,$A$36:$A$70,LEFT(G$4,4)) -> 0 | H7: =1000000*SUMIFS($H$36:$H$70,$G$36:$G$70,$E7,$A$36:$A$70,LEFT(H$4,4)) -> 0 | I7: =1000000*SUMIFS($H$36:$H$70,$G$36:$G$70,$E7,$A$36:$A$70,LEFT(I$4,4)) -> 25375.678 | J7: =1000000*SUMIFS($H$36:$H$70,$G$36:$G$70,$E7,$A$36:$A$70,LEFT(J$4,4)) -> 0 | K7: =1000000*SUMIFS($H$36:$H$70,$G$36:$G$70,$E7,$A$36:$A$70,LEFT(K$4,4)) -> 0 | L7: =1000000*SUMIFS($H$36:$H$70,$G$36:$G$70,$E7,$A$36:$A$70,LEFT(L$4,4)) -> 24897.565 | M7: =1000000*SUMIFS($H$36:$H$70,$G$36:$G$70,$E7,$A$36:$A$70,LEFT(M$4,4)) -> 25000 | P7: YBD | Q7: =(SUM(F7:K7)/1000000) -> 0.025375678 | R7: =Q7/$Q$8 -> 0.028393238
A8: =I4 -> 2028F | B8: =SUM(I5:I7)/1000000 -> 0.3183105 | C8: =C7+B8 -> 0.56678626 | D8: =B11=I70 -> FALSE | E8: Overall | F8: =SUM(F5:F7) -> 0 | G8: =SUM(G5:G7) -> 89805.21 | H8: =SUM(H5:H7) -> 86697.826 | I8: =SUM(I5:I7) -> 318310.5 | J8: =SUM(J5:J7) -> 318098.3 | K8: =SUM(K5:K7) -> 80810.758 | L8: =SUM(L5:L7) -> 372379.83 | M8: =SUM(M5:M7) -> 25000 | P8: Total | Q8: =SUM(Q5:Q7) -> 0.89372259 | R8: =SUM(R5:R7) -> 1
A9: =J4 -> 2029F | B9: =SUM(J5:J7)/1000000 -> 0.3180983 | C9: =C8+B9 -> 0.88488457 | E9: Source: Colliers Database | P9: Source: Colliers International
A10: =K4 -> 2030F | B10: =SUM(K5:K7)/1000000 -> 0.080810758 | C10: =C9+B10 -> 0.96569532 | E10: Table: Future Supply by Submarkets by area (2025-2032)
A11: TOTAL | B11: =SUM(B5:B10) -> 0.89372259 | E11: Submarket | F11: 2025F | G11: 2026F | H11: 2027F | I11: 2028F | J11: 2029F | K11: 2030F | L11: 2031F | M11: 2032F | P11: Table: Future Supply Breakdown in next 3 years (2026-2028)
A12: Source: Colliers Database | E12: CBD | F12: =IFERROR(F5/F$8,) -> 0 | G12: =G5/G$8 -> 1 | H12: =H5/H$8 -> 1 | I12: =I5/I$8 -> 0.5582177 | J12: =J5/J$8 -> 1 | K12: =K5/K$8 -> 0.50152166 | L12: =L5/L$8 -> 0.17856485 | M12: =M5/M$8 -> 0 | P12: Supply Breakdown (2026 - 2028) | Q12: Area (Million pyeong) | R12: % of Total Supply
E13: GBD | F13: =IFERROR(F6/F$8,) -> 0 | G13: =G6/G$8 -> 0 | H13: =H6/H$8 -> 0 | I13: =I6/I$8 -> 0.36206241 | J13: =J6/J$8 -> 0 | K13: =K6/K$8 -> 0.49847834 | L13: =L6/L$8 -> 0.75457448 | M13: =M6/M$8 -> 0 | P13: CBD | Q13: {=SUM(G5:I5/1000000)} -> 0.35418959 | R13: =Q13/$Q$16 -> 0.71580417
E14: YBD | F14: =IFERROR(F7/F$8,) -> 0 | G14: =G7/G$8 -> 0 | H14: =H7/H$8 -> 0 | I14: =I7/I$8 -> 0.079719892 | J14: =J7/J$8 -> 0 | K14: =K7/K$8 -> 0 | L14: =L7/L$8 -> 0.06686067 | M14: =M7/M$8 -> 1 | P14: GBD | Q14: {=SUM(G6:I6/1000000)} -> 0.11524826 | R14: =Q14/$Q$16 -> 0.23291252
E15: Overall | F15: =IFERROR(F8/F$8,) -> 0 | G15: =G8/G$8 -> 1 | H15: =H8/H$8 -> 1 | I15: =I8/I$8 -> 1 | J15: =J8/J$8 -> 1 | K15: =K8/K$8 -> 1 | L15: =L8/L$8 -> 1 | M15: =M8/M$8 -> 1 | P15: YBD | Q15: {=SUM(G7:I7/1000000)} -> 0.025375678 | R15: =Q15/$Q$16 -> 0.051283315
P16: Total | Q16: =SUM(Q13:Q15) -> 0.49481353 | R16: =SUM(R13:R15) -> 1
E17: Table: Number of Future Projects by Submarkets (2025-2032) | P17: Source: Colliers International
E18: Submarket | F18: 2025F | G18: 2026F | H18: 2027F | I18: 2028F | J18: 2029F | K18: 2030F | L18: 2031F | M18: 2032F
E19: CBD | F19: =COUNTIFS($A$36:$A$69,LEFT(F$18,4),$G$36:$G$69,$E19) -> 0 | G19: =COUNTIFS($A$36:$A$69,LEFT(G$18,4),$G$36:$G$69,$E19) -> 4 | H19: =COUNTIFS($A$36:$A$69,LEFT(H$18,4),$G$36:$G$69,$E19) -> 6 | I19: =COUNTIFS($A$36:$A$69,LEFT(I$18,4),$G$36:$G$69,$E19) -> 6 | J19: =COUNTIFS($A$36:$A$69,LEFT(J$18,4),$G$36:$G$69,$E19) -> 6 | K19: =COUNTIFS($A$36:$A$69,LEFT(K$18,4),$G$36:$G$69,$E19) -> 1 | L19: =COUNTIFS($A$36:$A$69,LEFT(L$18,4),$G$36:$G$69,$E19) -> 3 | M19: =COUNTIFS($A$36:$A$69,LEFT(M$18,4),$G$36:$G$69,$E19) -> 0
E20: GBD | F20: =COUNTIFS($A$36:$A$69,LEFT(F$18,4),$G$36:$G$69,$E20) -> 0 | G20: =COUNTIFS($A$36:$A$69,LEFT(G$18,4),$G$36:$G$69,$E20) -> 0 | H20: =COUNTIFS($A$36:$A$69,LEFT(H$18,4),$G$36:$G$69,$E20) -> 0 | I20: =COUNTIFS($A$36:$A$69,LEFT(I$18,4),$G$36:$G$69,$E20) -> 2 | J20: =COUNTIFS($A$36:$A$69,LEFT(J$18,4),$G$36:$G$69,$E20) -> 0 | K20: =COUNTIFS($A$36:$A$69,LEFT(K$18,4),$G$36:$G$69,$E20) -> 1 | L20: =COUNTIFS($A$36:$A$69,LEFT(L$18,4),$G$36:$G$69,$E20) -> 1 | M20: =COUNTIFS($A$36:$A$69,LEFT(M$18,4),$G$36:$G$69,$E20) -> 0
E21: YBD | F21: =COUNTIFS($A$36:$A$69,LEFT(F$18,4),$G$36:$G$69,$E21) -> 0 | G21: =COUNTIFS($A$36:$A$69,LEFT(G$18,4),$G$36:$G$69,$E21) -> 0 | H21: =COUNTIFS($A$36:$A$69,LEFT(H$18,4),$G$36:$G$69,$E21) -> 0 | I21: =COUNTIFS($A$36:$A$69,LEFT(I$18,4),$G$36:$G$69,$E21) -> 2 | J21: =COUNTIFS($A$36:$A$69,LEFT(J$18,4),$G$36:$G$69,$E21) -> 0 | K21: =COUNTIFS($A$36:$A$69,LEFT(K$18,4),$G$36:$G$69,$E21) -> 0 | L21: =COUNTIFS($A$36:$A$69,LEFT(L$18,4),$G$36:$G$69,$E21) -> 1 | M21: =COUNTIFS($A$36:$A$69,LEFT(M$18,4),$G$36:$G$69,$E21) -> 1
E22: Overall | F22: =SUM(F19:F21) -> 0 | G22: =SUM(G19:G21) -> 4 | H22: =SUM(H19:H21) -> 6 | I22: =SUM(I19:I21) -> 10 | J22: =SUM(J19:J21) -> 6 | K22: =SUM(K19:K21) -> 2 | L22: =SUM(L19:L21) -> 5 | M22: =SUM(M19:M21) -> 1
A24: Table: Completed Projects
A25: Year | B25: Quarter | C25: Status | D25: Project | E25: Developer | F25: Location | G25: Submarket | H25: GFA (Million pyeong)
A26: 2024 | B26: 1Q | C26: Completed | D26: TP Tower | E26: Samsung C&T | F26: Yeoido | G26: YBD | H26: 0.042861521 | J26: S
A27: 2024 | B27: 2Q | C27: Completed | D27: Meritz Bongrae | E27: Doosan Construction | F27: Bongrae | G27: CBD | H27: 0.012746886
A28: 2024 | B28: 4Q | C28: Completed | D28: Centrepoint Gangnam | E28: Mastern | F28: Gangnam | G28: GBD | H28: 0.0081813968
A29: 2025 | B29: 1Q | C29: Completed | D29: Jung-gu Cho-dong (Project 107) | E29: MPLUS AMC | F29: Junggu | G29: CBD | H29: ='Existing Supply'!D24/1000000 -> 0
A30: 2025 | B30: 2Q | C30: Completed | D30: Baekam Building (OPUS 459) | E30: Taeyoung Group | F30: Seocho | G30: GBD | H30: 0.0081829275
A31: 2025 | B31: 2Q | C31: Completed | D31: KT Gwanghwamun Bld (WEST) | E31: Gunwon Engineering | F31: Junggu | G31: CBD | H31: 0.020253747
A32: Source: Colliers Database
A34: Table: Proposed Projects Information (2026-2032)
A35: Year | B35: Quarter | C35: Status | D35: Proposed Project | E35: Developer | F35: Location | G35: Submarket | H35: Estimated GFA (Million pyeong) | I35: Remark (Changes) | P35: [Summary]
A36: 2026 | B36: 3Q | C36: U/C | D36: Gongpyeong District 15, 16 | E36: Hyundai Engineering | F36: Jongro-gu | G36: CBD | H36: 0.03509605 | P36: Between 2025 and 2032, Seoul’s major business districts are expected to see a substantial pipeline of new office supply, with notable concentration in the CBD and GBD. From 2026 onward, the CBD will lead with steady deliveries, accounting for over half of the new supply in most years and peaking at more than 318,000 pyeong in 2029. The GBD is also set to receive significant injections, particularly in 2028–2031 when more than 436,000 pyeong is forecast, reinforcing its role as a core office hub. The YBD pipeline remains limited, though it will see modest additions in 2028 and from 2031 onwards, including a 25,000-pyeong project in 2032.
A37: 2026 | B37: 3Q | C37: U/C | D37: Euljiro Central Office 3ga 12 District | E37: Eastern Development | F37: Jung-gu | G37: CBD | H37: =(41984*0.3025)/1000000 -> 0.01270016
A38: 2026 | B38: 4Q | C38: U/C | D38: Supyo City Environment Renovation Office Development Project | E38: n.a. | F38: Jung-gu | G38: CBD | H38: 0.032035
A39: 2026 | B39: 4Q | C39: U/C | D39: The 3rd Seoul City Hall | E39: Seoul Metropolitan Government | F39: Jung-gu | G39: CBD | H39: 0.009974 | I39: The Seoul City departments are currently residing in 'Seoul City Square Building' and will move into their new building after completion
A40: 2027 | B40: 1Q | C40: B/C | D40: Eulji Finance Center (Euljiro 3ga 1, 2 District) | E40: n.a. | F40: Jung-gu | G40: CBD | H40: 0.019659173
A41: 2027 | B41: 1Q | C41: B/C | D41: Euljiro 3ga 6 District | E41: n.a. | F41: Jung-gu | G41: CBD | H41: 0.015759506
A42: 2027 | B42: 2Q | C42: B/C | D42: Euljiro 3ga 12 District | E42: Euljiro 75 PFV | F42: Jung-gu | G42: CBD | H42: 0.013583
A43: 2027 | B43: 4Q | C43: B/C | D43: Euljiro 3ga 10 District | E43: n.a. | F43: Jung-gu | G43: CBD | H43: =9459.147775/1000000 -> 0.0094591478
...

Sheet Net Absorption
A1: Seoul Net Absorption
A3: Table: Overall Net Absorption | G3: [Overall summary]
A4: Year | B4: Yearly Net Absorption (pyeong) | C4: Quarter | D4: Quarterly Net Absorption (pyeong) | E4: Quarterly Net Absorption (sq. m.) | G4: In Q4 2025, Seoul’s office market recorded negative net absorption of 24,992 pyeong, partially offsetting the strong positive absorption achieved in Q2 and Q3. While 2025 year-to-date absorption remained marginally positive at 11,528 pyeong, the Q4 reversal reflects year-end lease rationalisation and selective tenant consolidation, rather than a broad-based weakening in demand. The quarterly volatility highlights an increasingly uneven absorption pattern, with occupier expansion remaining concentrated in specific sectors and locations, while some tenants deferred or adjusted space commitments toward year-end.
A5: 2019 | B5: =SUM(D5:D8) -> 91600.025 | C5: 1Q | D5: =SUM(C61,G61,K61) -> 24553.925 | E5: =Table41214[[#This Row],[Quarterly Net Absorption (pyeong)]]/0.3025 -> 81170
C6: 2Q | D6: =SUM(C62,G62,K62) -> 9204.47 | E6: =Table41214[[#This Row],[Quarterly Net Absorption (pyeong)]]/0.3025 -> 30428
C7: 3Q | D7: =SUM(C63,G63,K63) -> 50278.525 | E7: =Table41214[[#This Row],[Quarterly Net Absorption (pyeong)]]/0.3025 -> 166210
C8: 4Q | D8: =SUM(C64,G64,K64) -> 7563.105 | E8: =Table41214[[#This Row],[Quarterly Net Absorption (pyeong)]]/0.3025 -> 25002
A9: 2020 | B9: =SUM(D9:D12) -> 46861.485 | C9: 1Q | D9: =SUM(C65,G65,K65) -> 1201.53 | E9: =Table41214[[#This Row],[Quarterly Net Absorption (pyeong)]]/0.3025 -> 3972
C10: 2Q | D10: =SUM(C66,G66,K66) -> 12314.472 | E10: =Table41214[[#This Row],[Quarterly Net Absorption (pyeong)]]/0.3025 -> 40709
C11: 3Q | D11: =SUM(C67,G67,K67) -> 15210.305 | E11: =Table41214[[#This Row],[Quarterly Net Absorption (pyeong)]]/0.3025 -> 50282
C12: 4Q | D12: =SUM(C68,G68,K68) -> 18135.178 | E12: =Table41214[[#This Row],[Quarterly Net Absorption (pyeong)]]/0.3025 -> 59951
A13: 2021 | B13: =SUM(D13:D16) -> 150786.27 | C13: 1Q | D13: =SUM(C69,G69,K69) -> 38056.618 | E13: =Table41214[[#This Row],[Quarterly Net Absorption (pyeong)]]/0.3025 -> 125807
C14: 2Q | D14: =SUM(C70,G70,K70) -> 17006.247 | E14: =Table41214[[#This Row],[Quarterly Net Absorption (pyeong)]]/0.3025 -> 56219
C15: 3Q | D15: =SUM(C71,G71,K71) -> 43207.588 | E15: =Table41214[[#This Row],[Quarterly Net Absorption (pyeong)]]/0.3025 -> 142835
C16: 4Q | D16: =SUM(C72,G72,K72) -> 52515.815 | E16: =Table41214[[#This Row],[Quarterly Net Absorption (pyeong)]]/0.3025 -> 173606 | G16: [GBD - Projection]
A17: 2022 | B17: =SUM(D17:D20) -> 126882.72 | C17: 1Q | D17: =SUM(C73,G73,K73) -> 63809.652 | E17: =Table41214[[#This Row],[Quarterly Net Absorption (pyeong)]]/0.3025 -> 210941 | G17: Despite the negative citywide absorption in Q4, the GBD continued to demonstrate relative resilience, supported by strong tenant retention and structurally limited Grade A supply. Demand in the district remains underpinned by technology-, AI-, and data-driven occupiers, suggesting that the Q4 decline is largely attributable to CBD-led move-outs and timing effects, rather than a deterioration in GBD fundamentals. As such, the GBD is expected to maintain tight vacancy conditions relative to other submarkets heading into 2026.
C18: 2Q | D18: =SUM(C74,G74,K74) -> 21129.322 | E18: =Table41214[[#This Row],[Quarterly Net Absorption (pyeong)]]/0.3025 -> 69849
C19: 3Q | D19: =SUM(C75,G75,K75) -> 25859.515 | E19: =Table41214[[#This Row],[Quarterly Net Absorption (pyeong)]]/0.3025 -> 85486
C20: 4Q | D20: =SUM(C76,G76,K76) -> 16084.227 | E20: =Table41214[[#This Row],[Quarterly Net Absorption (pyeong)]]/0.3025 -> 53171
A21: 2023 | B21: =SUM(D21:D24) -> 39036 | C21: 1Q | D21: =SUM(C77,G77,K77) -> -14436 | E21: =D21/0.3025 -> -47722.314
C22: 2Q | D22: =SUM(C78,G78,K78) -> 21070 | E22: =D22/0.3025 -> 69652.893
C23: 3Q | D23: =SUM(C79,G79,K79) -> 45692 | E23: =D23/0.3025 -> 151047.93
C24: 4Q | D24: =SUM(C80,G80,K80) -> -13290 | E24: =D24/0.3025 -> -43933.884
A25: 2024 | B25: =SUM(D25:D28) -> -59209 | C25: 1Q | D25: =SUM(C81,G81,K81) -> -12407 | E25: =D25/0.3025 -> -41014.876
C26: 2Q | D26: =SUM(C82,G82,K82) -> -32126 | E26: =D26/0.3025 -> -106201.65
C27: 3Q | D27: =SUM(C83,G83,K83) -> -36156 | E27: =D27/0.3025 -> -119523.97
C28: 4Q | D28: =SUM(C84,G84,K84) -> 21480 | E28: =D28/0.3025 -> 71008.264
A29: 2025 YTD | B29: =SUM(D29:D32) -> 11528 | C29: 1Q | D29: =SUM(C85,G85,K85) -> -79876 | E29: =D29/0.3025 -> -264052.89
C30: 2Q | D30: =SUM(C86,G86,K86) -> 74554 | E30: =D30/0.3025 -> 246459.5
C31: 3Q | D31: =SUM(C87,G87,K87) -> 41842 | E31: =D31/0.3025 -> 138320.66
C32: 4Q | D32: =SUM(C88,G88,K88) -> -24992 | E32: =D32/0.3025 -> -82618.182
A33: Source: Colliers Database
B59: Table: Net Absorption by Submarkets_Unit: pyeong
B60: CBD | C60: Net Absorption | F60: GBD | G60: Net Absorption | J60: YBD | K60: Net Absorption | O60: =(-59209-39036)/39036 -> -2.5167794
B61: 1Q 2019 | C61: 6009.465 | F61: 1Q 2019 | G61: 15470.153 | J61: 1Q 2019 | K61: 3074.3075
B62: 2Q 2019 | C62: -2695.88 | F62: 2Q 2019 | G62: 10922.065 | J62: 2Q 2019 | K62: 978.285
B63: 3Q 2019 | C63: 34631.107 | D63: FY 2019 | F63: 3Q 2019 | G63: 6069.0575 | H63: FY 2019 | J63: 3Q 2019 | K63: 9578.36 | L63: FY 2019
B64: 4Q 2019 | C64: 28560.84 | D64: =SUM(C61:C64) -> 66505.533 | F64: 4Q 2019 | G64: -14949.247 | H64: =SUM(G61:G64) -> 17512.027 | J64: 4Q 2019 | K64: -6048.4875 | L64: =SUM(K61:K64) -> 7582.465
B65: 1Q 2020 | C65: 9336.965 | F65: 1Q 2020 | G65: -2520.43 | J65: 1Q 2020 | K65: -5615.005
B66: 2Q 2020 | C66: -2073.6375 | F66: 2Q 2020 | G66: -391.1325 | J66: 2Q 2020 | K66: 14779.243
...

Sheet Rent
A1: Seoul Grade A Office Building Rents
A3: Table: Major Submarket Rents
A5: Unit: KRW/pyeong/month | B5: Q1 2019 | C5: Q2 2019 | D5: Q3 2019 | E5: Q4 2019 | F5: Q1 2020 | G5: Q2 2020 | H5: Q3 2020 | I5: Q4 2020 | J5: Q1 2021 | K5: Q2 2021 | L5: Q3 2021 | M5: Q4 2021 | N5: Q1 2022 | O5: Q2 2022 | P5: Q3 2022 | Q5: Q4 2022 | R5: Q1 2023 | S5: Q2 2023 | T5: Q3 2023
A6: CBD | B6: 106690.91 | C6: 106611.57 | D6: 106700.83 | E6: 107150.41 | F6: 107965.48 | G6: 108483.68 | H6: 108532.23 | I6: 109347.13 | J6: 110087.23 | K6: 110500.32 | L6: 110655.31 | M6: 110819.77 | N6: 111240.75 | O6: 111819.62 | P6: =34147/0.3025 -> 112882.64 | Q6: 115064.46 | R6: 117533.88 | S6: =35638/0.3025 -> 117811.57 | T6: =35946/0.3025 -> 118829.75
A7: GBD | B7: 91834.711 | C7: 92148.76 | D7: 92195.041 | E7: 92039.669 | F7: 93927.964 | G7: 94540.006 | H7: 95338.843 | I7: 96061.323 | J7: 98407.796 | K7: 98709.599 | L7: 98818.294 | M7: 98883.512 | N7: 99122.641 | O7: 100450.68 | P7: =30866/0.3025 -> 102036.36 | Q7: 104340.5 | R7: 108419.83 | S7: =33795/0.3025 -> 111719.01 | T7: =34656/0.3025 -> 114565.29
A8: YBD | B8: 77887.603 | C8: 77976.86 | D8: 78204.959 | E8: 78704.132 | F8: 79204.189 | G8: 79556.46 | H8: 82717.355 | I8: 82221.638 | J8: 82521.629 | K8: 83220.459 | L8: 84603.811 | M8: 85699.223 | N8: 86362.528 | O8: 87526.273 | P8: =26741/0.3025 -> 88400 | Q8: 89854.545 | R8: =28293/0.3025 -> 93530.579 | S8: =28497/0.3025 -> 94204.959 | T8: =29301/0.3025 -> 96862.81
A9: Seoul Overall Rent | B9: 95550.413 | C9: 96000 | D9: 96102.479 | E9: 96317.355 | F9: 97438.564 | G9: 98233.846 | H9: 98449.587 | I9: 98789.349 | J9: 99896.336 | K9: 100425.42 | L9: 100885.09 | M9: 101222.85 | N9: 101636.41 | O9: 102597.4 | P9: =O9*1.012 -> 103828.57 | Q9: 105857.85 | R9: 109130.58 | S9: =33434/0.3025 -> 110525.62 | T9: =34009/0.3025 -> 112426.45
A10: Source: Colliers Database
A11: CBD (QoQ) | B11: 0.0070204999 | C11: -0.00074363265 | D11: 0.0008372093 | E11: 0.0042135267 | F11: 0.0076067133 | G11: 0.0047997084 | H11: 0.00044755963 | I11: =I6/H6-1 -> 0.0075083199 | J11: =J6/I6-1 -> 0.0067684061 | K11: =K6/J6-1 -> 0.0037523793 | L11: =L6/K6-1 -> 0.0014025723 | M11: =M6/L6-1 -> 0.001486269 | N11: =N6/M6-1 -> 0.0037987829 | O11: =O6/N6-1 -> 0.0052037801 | P11: =P6/O6-1 -> 0.0095065857 | ... T11: =T6/S6-1 -> 0.0086424603
A12: GBD (QoQ) | B12: 0.0065217391 | C12: 0.0034197264 | D12: 0.00050224215 | E12: -0.0016852522 | F12: 0.020516091 | G12: 0.0065160861 | H12: 0.00844972 | I12: =I7/H7-1 -> 0.0075780268 | J12: =J7/I7-1 -> 0.024426824 | K12: =K7/J7-1 -> 0.0030668606 | L12: =L7/K7-1 -> 0.001101161 | M12: =M7/L7-1 -> 0.00065996988 | N12: =N7/M7-1 -> 0.0024182936 | O12: =O7/N7-1 -> 0.013397923 | P12: =P7/O7-1 -> 0.01578571 | ... T12: =T7/S7-1 -> 0.025477142
A13: YBD (QoQ) | B13: 0.0032361082 | C13: 0.0011459615 | D13: 0.0029252162 | E13: 0.0063828888 | F13: 0.0063536283 | G13: 0.0044476327 | H13: 0.039731471 | I13: =I8/H8-1 -> -0.0059929064 | J13: =J8/I8-1 -> 0.0036485609 | K13: =K8/J8-1 -> 0.0084684488 | L13: =L8/K8-1 -> 0.016622741 | M13: =M8/L8-1 -> 0.012947546 | N13: =N8/M8-1 -> 0.0077399226 | O13: =O8/N8-1 -> 0.013475112 | P13: =P8/O8-1 -> 0.0099824564 | ... T13: =T8/S8-1 -> 0.028213496
A14: Seoul Overall (QoQ) | B14: 0.0062315057 | C14: 0.0047052311 | D14: 0.0010674931 | E14: 0.0022359052 | F14: 0.011640771 | G14: 0.0081618826 | H14: 0.0021961984 | I14: =I9/H9-1 -> 0.0034511332 | J14: =J9/I9-1 -> 0.011205525 | K14: =K9/J9-1 -> 0.0052963218 | L14: =L9/K9-1 -> 0.0045772633 | M14: =M9/L9-1 -> 0.0033479432 | N14: =N9/M9-1 -> 0.0040855995 | O14: =O9/N9-1 -> 0.0094551852 | P14: =P9/O9-1 -> 0.012 | ... T14: =T9/S9-1 -> 0.017198062
A15: Source: Colliers Database
A16: CBD (YoY) | B16: 0.030186219 | C16: 0.025209015 | D16: 0.011469399 | E16: 0.011357609 | F16: 0.011946347 | G16: 0.017560085 | H16: 0.017163925 | I16: =I6/E6-1 -> 0.020501208 | J16: =J6/F6-1 -> 0.019652173 | K16: =K6/G6-1 -> 0.018589363 | L16: =L6/H6-1 -> 0.019561693 | M16: =M6/I6-1 -> 0.013467597 | N16: =N6/J6-1 -> 0.010478214 | O16: =O6/K6-1 -> 0.01193934 | P16: =P6/L6-1 -> 0.020128624 | ... T16: =T6/P6-1 -> 0.052683984
A17: GBD (YoY) | B17: 0.0365533 | C17: 0.036014272 | D17: 0.012819582 | E17: 0.0087681159 | F17: 0.022793701 | G17: 0.025949845 | H17: 0.034099466 | I17: =I7/E7-1 -> 0.043694788 | J17: =J7/F7-1 -> 0.047694344 | K17: =K7/G7-1 -> 0.044104005 | L17: =L7/H7-1 -> 0.036495634 | M17: =M7/I7-1 -> 0.029379028 | N17: =N7/J7-1 -> 0.0072641054 | O17: =O7/K7-1 -> 0.017638397 | P17: =P7/L7-1 -> 0.03256552 | ... T17: =T7/P7-1 -> 0.12278883
A18: YBD (YoY) | B18: 0.0061861325 | C18: 0.0073454049 | D18: 0.0090854803 | E18: 0.01375346 | F18: 0.016903662 | G18: 0.0202573 | H18: 0.057699624 | I18: =I8/E8-1 -> 0.044692771 | J18: =J8/F8-1 -> 0.041884648 | K18: =K8/G8-1 -> 0.046055325 | L18: =L8/H8-1 -> 0.022806043 | M18: =M8/I8-1 -> 0.042295249 | N18: =N8/J8-1 -> 0.046544154 | O18: =O8/K8-1 -> 0.051739849 | P18: =P8/L8-1 -> 0.04487019 | ... T18: =T8/P8-1 -> 0.095733144
A19: Seoul Overall (YoY) | B19: 0.063366138 | C19: 0.065297139 | D19: 0.052140763 | E19: 0.014308094 | F19: 0.019760777 | G19: 0.023269227 | H19: 0.024422964 | I19: =I9/E9-1 -> 0.025665095 | J19: =J9/F9-1 -> 0.025223815 | K19: =K9/G9-1 -> 0.022309758 | L19: =L9/H9-1 -> 0.02473861 | M19: =M9/I9-1 -> 0.024633231 | N19: =N9/J9-1 -> 0.01741876 | O19: =O9/K9-1 -> 0.021627774 | P19: =P9/L9-1 -> 0.029176495 | ... T19: =T9/P9-1 -> 0.082808427
A20: Source: Colliers Database
A22: Unit: KRW/pyeong/month | B22: Q4 2023 | C22: Q1 2024 | D22: Q2 2024 | E22: Q3 2024 | F22: Q4 2024 | G22: Q1 2025 | H22: Q2 2025 | I22: Q3 2025 | J22: Q4 2025
A23: CBD | B23: =36615/0.3025 -> 121041.32 | C23: =36948/0.3025 -> 122142.15 | D23: 123203.31 | E23: =37465/0.3025 -> 123851.24 | F23: =38088/0.3025 -> 125910.74 | G23: =38796/0.3025 -> 128251.24 | H23: =39507/0.3025 -> 130601.65 | I23: =39921/0.3025 -> 131970.25 | J23: =40367/0.3025 -> 133444.63
A24: GBD | B24: =36411/0.3025 -> 120366.94 | C24: =36477/0.3025 -> 120585.12 | D24: 122330.58 | E24: =38448/0.3025 -> 127100.83 | F24: =38989/0.3025 -> 128889.26 | G24: =39113/0.3025 -> 129299.17 | H24: =40469/0.3025 -> 133781.82 | I24: =40854/0.3025 -> 135054.55 | J24: =41436/0.3025 -> 136978.51
A25: YBD | B25: =29841/0.3025 -> 98647.934 | C25: =30692/0.3025 -> 101461.16 | D25: 102294.21 | E25: =31599/0.3025 -> 104459.5 | F25: =31925/0.3025 -> 105537.19 | G25: =32832/0.3025 -> 108535.54 | H25: =32923/0.3025 -> 108836.36 | I25: =33051/0.3025 -> 109259.5 | J25: =33441/0.3025 -> 110548.76 | V25: [Overall Summary]
A26: Seoul Overall Rent | B26: =35016/0.3025 -> 115755.37 | C26: =35303/0.3025 -> 116704.13 | D26: 117960.33 | E26: =36401/0.3025 -> 120333.88 | F26: =36933/0.3025 -> 122092.56 | G26: =37499/0.3025 -> 123963.64 | H26: =38290/0.3025 -> 126578.51 | I26: =38627/0.3025 -> 127692.56 | J26: =39105/0.3025 -> 129272.73 | V26: In Q4 2025, Seoul’s overall Grade A office rent rose to KRW 129,273 per pyeong per month, marking a 1.2% quarter-on-quarter increase and a 5.9% year-on-year growth. Compared to the steady momentum observed in Q3, rental growth in Q4 reflected a year-end consolidation of leasing demand, with limited new Grade A supply entering the market and occupier decisions increasingly focused on securing long-term space ahead of anticipated cost pressures. Landlords of prime assets were therefore able to translate tight availability into incremental rental uplifts, particularly in well-located, institutionally managed buildings. While macroeconomic uncertainty continued to temper broader office demand, the imbalance between constrained supply and sustained demand for core Grade A space supported rental stability and reinforced the market’s defensive characteristics entering 2026.
A27: Source: Colliers Database
A28: CBD (QoQ) | B28: =B23/T6-1 -> 0.01861125 | C28: =C23/B23-1 -> 0.0090946333 | D28: =D23/C23-1 -> 0.0086878857 | E28: =E23/D23-1 -> 0.0052590625 | F28: =F23/E23-1 -> 0.016628854 | G28: =G23/F23-1 -> 0.018588532 | H28: =H23/G23-1 -> 0.018326632 | I28: =I23/H23-1 -> 0.010479156 | J28: =J23/I23-1 -> 0.011172065
A29: GBD (QoQ) | B29: =B24/T7-1 -> 0.050640582 | C29: =C24/B24-1 -> 0.001812639 | D29: =D24/C24-1 -> 0.014474875 | E29: =E24/D24-1 -> 0.03899473 | F29: =F24/E24-1 -> 0.014070953 | G29: =G24/F24-1 -> 0.0031803842 | H29: =H24/G24-1 -> 0.03466878 | I29: =I24/H24-1 -> 0.0095134547 | J29: =J24/I24-1 -> 0.014245851
A30: YBD (QoQ) | B30: =B25/T8-1 -> 0.018429405 | C30: =C25/B25-1 -> 0.028517811 | D30: =D25/C25-1 -> 0.0082106086 | E30: =E25/D25-1 -> 0.02116727 | F30: =F25/E25-1 -> 0.010316782 | G30: =G25/F25-1 -> 0.028410337 | H30: =H25/G25-1 -> 0.0027716862 | I30: =I25/H25-1 -> 0.0038878596 | J30: =J25/I25-1 -> 0.011799946
A31: Seoul Overall (QoQ) | B31: =B26/T9-1 -> 0.029609809 | C31: =C26/B26-1 -> 0.0081962531 | D31: =D26/C26-1 -> 0.010763958 | E31: =E26/D26-1 -> 0.020121627 | F31: =F26/E26-1 -> 0.014614983 | G31: =G26/F26-1 -> 0.015325048 | H31: =H26/G26-1 -> 0.021093896 | I31: =I26/H26-1 -> 0.0088012536 | J31: =J26/I26-1 -> 0.012374764
A32: Source: Colliers Database
A33: CBD (YoY) | B33: =B23/Q6-1 -> 0.051943575 | C33: =C23/R6-1 -> 0.039207965 | D33: =D23/S6-1 -> 0.045765756 | E33: =E23/T6-1 -> 0.042257831 | F33: =F23/B23-1 -> 0.040229414 | G33: =G23/C23-1 -> 0.050016239 | H33: =H23/D23-1 -> 0.060049907 | I33: =I23/E23-1 -> 0.065554518 | J33: =J23/F23-1 -> 0.059835119
A34: GBD (YoY) | B34: =B24/Q7-1 -> 0.15359757 | C34: =C24/R7-1 -> 0.11220538 | D34: =D24/S7-1 -> 0.094984465 | E34: =E24/T7-1 -> 0.10941828 | F34: =F24/B24-1 -> 0.070802779 | G34: =G24/C24-1 -> 0.072264715 | H34: =H24/D24-1 -> 0.093608972 | I34: =I24/E24-1 -> 0.062578027 | J34: =J24/F24-1 -> 0.062761292
A35: YBD (YoY) | B35: =B25/Q8-1 -> 0.097862477 | C35: =C25/R8-1 -> 0.084791291 | D35: =D25/S8-1 -> 0.085868688 | E35: =E25/T8-1 -> 0.078427357 | F35: =F25/B25-1 -> 0.069836802 | G35: =G25/C25-1 -> 0.06972501 | H35: =H25/D25-1 -> 0.06395424 | I35: =I25/E25-1 -> 0.045950821 | J35: =J25/F25-1 -> 0.047486296
A36: Seoul Overall (YoY) | B36: =B26/Q9-1 -> 0.09349822 | C36: =C26/R9-1 -> 0.069399006 | D36: =D26/S9-1 -> 0.067266854 | E36: =E26/T9-1 -> 0.070334323 | F36: =F26/B26-1 -> 0.054746402 | G36: =G26/C26-1 -> 0.062204345 | H36: =H26/D26-1 -> 0.073060001 | I36: =I26/E26-1 -> 0.061152166 | J36: =J26/F26-1 -> 0.058809195
A37: Source: Colliers Database
V38: [GBD]
V39: In Q4 2025, GBD headline office rents increased to KRW 136,979 per pyeong per month, maintaining the highest rental level among Seoul’s major business districts. Rents rose by 1.4% quarter-on-quarter, while year-on-year growth moderated to 6.3%, reflecting a normalization of leasing activity toward year-end. Despite this moderation, GBD continued to outperform the broader Seoul market, supported by limited Grade A supply, high tenant retention, and sustained demand from technology and multinational occupiers, reinforcing its position as Seoul’s leading office submarket heading into 2026.
A52: Unit: KRW/pyeong/month | B52: Q1 2019 | C52: Q2 2019 | D52: Q3 2019 | E52: Q4 2019 | F52: Q1 2020 | G52: Q2 2020 | H52: Q3 2020 | I52: Q4 2020 | J52: Q1 2021 | K52: Q2 2021 | L52: Q3 2021 | M52: Q4 2021 | N52: Q1 2022 | O52: Q2 2022 | P52: Q3 2022 | Q52: Q4 2022 | R52: Q1 2023 | S52: Q2 2023 | T52: Q3 2023 | U52: Q4 2023 | V52: Q1 2024 | W52: Q2 2024 | X52: Q3 2024 | Y52: Q4 2024 | Z52: Q1 2025 | AA52: Q2 2025 | AB52: Q3 2025 | AC52: Q4 2025 | AD52: Q1 2026 | AE52: Q2 2026 | AF52: Q3 2026 | AG52: Q4 2026
A53: CBD | B53: 106690.91 | C53: 106611.57 | D53: 106700.83 | E53: 107150.41 | F53: 107965.48 | G53: 108483.68 | H53: 108532.23 | I53: 109347.13 | J53: 110087.23 | K53: 110500.32 | L53: 110655.31 | M53: 110819.77 | N53: 111240.75 | O53: 111819.62 | P53: =34147/0.3025 -> 112882.64 | Q53: 115064.46 | R53: 117533.88 | S53: =35638/0.3025 -> 117811.57 | T53: =35946/0.3025 -> 118829.75 | U53: =36615/0.3025 -> 121041.32 | V53: =36948/0.3025 -> 122142.15 | W53: =D23 -> 123203.31 | X53: =E23 -> 123851.24 | Y53: =F23 -> 125910.74 | Z53: =G23 -> 128251.24 | AA53: =H23 -> 130601.65 | AB53: =I23 -> 131970.25 | AC53: =J23 -> 133444.63 | AD53: =K23 -> 0 | ... AG53: =N23 -> 0
A54: GBD | B54: 91834.711 | C54: 92148.76 | D54: 92195.041 | E54: 92039.669 | F54: 93927.964 | G54: 94540.006 | H54: 95338.843 | I54: 96061.323 | J54: 98407.796 | K54: 98709.599 | L54: 98818.294 | M54: 98883.512 | N54: 99122.641 | O54: 100450.68 | P54: =30866/0.3025 -> 102036.36 | Q54: 104340.5 | R54: 108419.83 | S54: =33795/0.3025 -> 111719.01 | T54: =34656/0.3025 -> 114565.29 | U54: =36411/0.3025 -> 120366.94 | V54: =36477/0.3025 -> 120585.12 | W54: =D24 -> 122330.58 | X54: =E24 -> 127100.83 | Y54: =F24 -> 128889.26 | Z54: =G24 -> 129299.17 | AA54: =H24 -> 133781.82 | AB54: =I24 -> 135054.55 | AC54: =J24 -> 136978.51 | AD54: =K24 -> 0 | ... AG54: =N24 -> 0
A55: YBD | B55: 77887.603 | C55: 77976.86 | D55: 78204.959 | E55: 78704.132 | F55: 79204.189 | G55: 79556.46 | H55: 82717.355 | I55: 82221.638 | J55: 82521.629 | K55: 83220.459 | L55: 84603.811 | M55: 85699.223 | N55: 86362.528 | O55: 87526.273 | P55: =26741/0.3025 -> 88400 | Q55: 89854.545 | R55: =28293/0.3025 -> 93530.579 | S55: =28497/0.3025 -> 94204.959 | T55: =29301/0.3025 -> 96862.81 | U55: =29841/0.3025 -> 98647.934 | V55: =30692/0.3025 -> 101461.16 | W55: =D25 -> 102294.21 | X55: =E25 -> 104459.5 | Y55: =F25 -> 105537.19 | Z55: =G25 -> 108535.54 | AA55: =H25 -> 108836.36 | AB55: =I25 -> 109259.5 | AC55: =J25 -> 110548.76 | AD55: =K25 -> 0 | ... AG55: =N25 -> 0
...

Sheet Vacancy Rate
A1: Seoul Vacancy Rate
R2: ▼
A3: Table: Major Submarket Vacancy Rates
A4: [Vacancy Rate] | B4: Q1 2011 | C4: Q2 2011 | D4: Q3 2011 | E4: Q4 2011 | F4: Q1 2012 | G4: In Q2 2025, the office absorption rate turned positive, indicating a recovery in demand compared to the negative absorption recorded in the previous quarter. Leasing demand increased primarily in newly completed buildings, with several relocations and expansions by firms in finance, law, and tax services across major business districts. In the CBD, the newly completed '107 Building' saw SK Telecom’s task force lease three floors and Samsung Fire & Marine Insurance lease 2.5 floors, contributing to the uptick. In YBD, Fubon Bank opened its first branch in IFC 2, and Kakao Pay Securities relocated its office from Pangyo to Yeouido Finance Center. | H4: Q3 2012 | I4: Q4 2012 | J4: Q1 2013 | K4: Q2 2013 | L4: Q3 2013 | M4: Q4 2013 | N4: Q1 2014 | O4: Q2 2014 | P4: Q3 2014 | Q4: Q4 2014 | R4: Q1 2015 | S4: Q2 2015 | T4: Q3 2015 | U4: Q4 2015
A5: CBD | B5: 0.148 | C5: 0.184 | D5: 0.266 | E5: 0.19 | F5: 0.181 | G5: 0.15 | H5: 0.127 | I5: 0.127 | J5: 0.135 | K5: 0.163 | L5: 0.14 | M5: 0.093 | N5: 0.097 | O5: 0.088 | P5: 0.091 | Q5: 0.107 | R5: 0.137 | S5: 0.147 | T5: 0.15 | U5: 0.149
A6: GBD | B6: 0.022 | C6: 0.023 | D6: 0.023 | E6: 0.026 | F6: 0.011 | G6: 0.044 | H6: 0.043 | I6: 0.04 | J6: 0.076 | K6: 0.075 | L6: 0.063 | M6: 0.071 | N6: 0.08 | O6: 0.089 | P6: 0.091 | Q6: 0.083 | R6: 0.086 | S6: 0.09 | T6: 0.086 | U6: 0.082
A7: YBD | B7: 0.039 | C7: 0.02 | D7: 0.05 | E7: 0.08 | F7: 0.051 | G7: 0.048 | H7: 0.043 | I7: 0.226 | J7: 0.214 | K7: 0.219 | L7: 0.236 | M7: 0.222 | N7: 0.229 | O7: 0.209 | P7: 0.21 | Q7: 0.167 | R7: 0.165 | S7: 0.178 | T7: 0.155 | U7: 0.142
A8: Seoul Overall Vacancy | B8: 0.076 | C8: 0.088 | D8: 0.136 | E8: 0.104 | F8: 0.092 | G8: 0.091 | H8: 0.079 | I8: 0.122 | J8: 0.132 | K8: 0.145 | L8: 0.138 | M8: 0.118 | N8: 0.124 | O8: 0.118 | P8: 0.12 | Q8: 0.114 | R8: 0.126 | S8: 0.134 | T8: 0.129 | U8: 0.125
A9: Source: Colliers Database
A10: QoQ Change | B10: Q1 2011 | C10: Q2 2011 | D10: Q3 2011 | E10: Q4 2011 | F10: Q1 2012 | G10: Q2 2012 | H10: Q3 2012 | I10: Q4 2012 | J10: Q1 2013 | K10: Q2 2013 | L10: Q3 2013 | M10: Q4 2013 | N10: Q1 2014 | O10: Q2 2014 | P10: Q3 2014 | Q10: Q4 2014 | R10: Q1 2015 | S10: Q2 2015 | T10: Q3 2015 | U10: Q4 2015
A11: CBD | C11: =C5-B5 -> 0.036 | D11: =D5-C5 -> 0.082 | E11: =E5-D5 -> -0.076 | F11: =F5-E5 -> -0.009 | G11: =G5-F5 -> -0.031 | H11: =H5-G5 -> -0.023 | I11: =I5-H5 -> 0 | J11: =J5-I5 -> 0.008 | ... U11: =U5-T5 -> -0.001
A12: GBD | C12: =C6-B6 -> 0.001 | D12: =D6-C6 -> 0 | E12: =E6-D6 -> 0.003 | F12: =F6-E6 -> -0.015 | G12: =G6-F6 -> 0.033 | H12: =H6-G6 -> -0.001 | I12: =I6-H6 -> -0.003 | J12: =J6-I6 -> 0.036 | ... U12: =U6-T6 -> -0.004
